<?xml version="1.0" encoding="UTF-8"?>
<!-- Generated by org.testng.reporters.JUnitXMLReporter -->
<testsuite ignored="1" hostname="DESKTOP-3GBRILF" failures="1" tests="8" name="KiemThu" time="165.619" errors="0" timestamp="2024-12-03T16:52:32 ICT">
  <testcase classname="com.nhom4.ProductTest" name="loginTest" time="2.066"/>
  <testcase classname="com.nhom4.ProductTest" name="updateProductTest" time="1.455"/>
  <testcase classname="com.nhom4.ProductTest" name="updateProductTest" time="61.516"/>
  <testcase classname="com.nhom4.ProductTest" name="updateProductTest" time="1.472"/>
  <testcase classname="com.nhom4.ProductTest" name="updateProductTest" time="31.092">
    <failure type="java.lang.AssertionError" message="expected [Giá phải lớn hơn 0] but found [Error
An unexpected error occurred
OK]">
      <![CDATA[java.lang.AssertionError: expected [Giá phải lớn hơn 0] but found [Error
An unexpected error occurred
OK]
at com.nhom4.ProductTest.updateProductTest(ProductTest.java:255)
at java.base/java.util.ArrayList.forEach(ArrayList.java:1597)
at com.intellij.rt.testng.IDEARemoteTestNG.run(IDEARemoteTestNG.java:65)
at com.intellij.rt.testng.RemoteTestNGStarter.main(RemoteTestNGStarter.java:105)
... Removed 28 stack frames]]>
    </failure>
  </testcase> <!-- updateProductTest -->
  <testcase classname="com.nhom4.ProductTest" name="updateProductTest" time="1.366"/>
  <testcase classname="com.nhom4.ProductTest" name="updateProductTest" time="1.005"/>
  <testcase classname="com.nhom4.ProductTest" name="updateProductTest" time="61.407"/>
  <testcase classname="com.nhom4.ProductTest" name="createProductTest" time="0.0">
    <ignored/>
  </testcase> <!-- createProductTest -->
</testsuite> <!-- KiemThu -->
